[INFO] Not enough data, proceeding...
Epoch Done
Traceback (most recent call last):
  File "/data_hdd1/hassan/projects/GPS/train.py", line 116, in <module>
    vy_ = model(vX)
  File "/home/user01/anaconda3/envs/pt/lib/python3.6/site-packages/torch/nn/modules/module.py", line 1102, in _call_impl
    return forward_call(*input, **kwargs)
  File "/data_hdd1/hassan/projects/GPS/GI_NN.py", line 25, in forward
    b = self.gnn(a)
  File "/home/user01/anaconda3/envs/pt/lib/python3.6/site-packages/torch/nn/modules/module.py", line 1102, in _call_impl
    return forward_call(*input, **kwargs)
  File "/home/user01/anaconda3/envs/pt/lib/python3.6/site-packages/torch/nn/modules/rnn.py", line 847, in forward
    self.check_forward_args(input, hx, batch_sizes)
  File "/home/user01/anaconda3/envs/pt/lib/python3.6/site-packages/torch/nn/modules/rnn.py", line 229, in check_forward_args
    self.check_input(input, batch_sizes)
  File "/home/user01/anaconda3/envs/pt/lib/python3.6/site-packages/torch/nn/modules/rnn.py", line 207, in check_input
    self.input_size, input.size(-1)))
RuntimeError: input.size(-1) must be equal to input_size. Expected 7, got 21