Traceback (most recent call last):
  File "/data_hdd1/hassan/projects/GPS/train.py", line 114, in <module>
    vy_ = model(vX)
  File "/home/user01/anaconda3/envs/pt/lib/python3.6/site-packages/torch/nn/modules/module.py", line 1102, in _call_impl
    return forward_call(*input, **kwargs)
  File "/data_hdd1/hassan/projects/GPS/GI_NN.py", line 24, in forward
    a = self.first_layer(x)
  File "/home/user01/anaconda3/envs/pt/lib/python3.6/site-packages/torch/nn/modules/module.py", line 1102, in _call_impl
    return forward_call(*input, **kwargs)
  File "/home/user01/anaconda3/envs/pt/lib/python3.6/site-packages/torch/nn/modules/conv.py", line 301, in forward
    return self._conv_forward(input, self.weight, self.bias)
  File "/home/user01/anaconda3/envs/pt/lib/python3.6/site-packages/torch/nn/modules/conv.py", line 298, in _conv_forward
    self.padding, self.dilation, self.groups)
RuntimeError: Given groups=1, weight of size [1, 9, 1], expected input[1, 7, 9] to have 9 channels, but got 7 channels instead
[INFO] Not enough data, proceeding...
Epoch Done